Workbook
Name a: #REF!
Name a: #REF!
Name a: #REF!
Name a: #REF!
Name a: #REF!
Name a: #REF!
Name a: #REF!
Name a: #REF!
Name a: #REF!
Name a: #REF!
Name a: #REF!
Name a: #REF!
Name a: #REF!
Name a: #REF!
Name a: #REF!
Name a: #REF!
Name a: #REF!
Name a: #REF!
Name a: #REF!
Name a: #REF!
Name a: #REF!
Name a: #REF!
Name a: #REF!
Name a: #REF!
Name a: #REF!
Name a: #REF!
Name a: #REF!
Name a: #REF!
Name a: #REF!
Name a: #REF!
Name a: #REF!
Name a: #REF!
Name a: #REF!
Name a: #REF!
Name a: #REF!
Name a: #REF!
Name a: #REF!
Name a: #REF!
Name a: #REF!
Name a: #REF!
Name a: #REF!
Name a: #REF!
Name a: #REF!
Name a: #REF!
Name a: #REF!
Name a: #REF!
Name a: #REF!
Name a: #REF!
Name a: #REF!
Name a: #REF!
Name a: #REF!
Name a: #REF!
Name a: #REF!
Name a: #REF!
Name a: #REF!
Name a: #REF!
Name a: #REF!
Name a: #REF!
Name a: #REF!
Name a: #REF!

Sheet 11.16
A1: Rotexmedica Lager
F2: Übertrag aus Vormonat:
F3: 0
A4: Datum | B4: Ein- lagerung | C4: Aus- lagerung | D4: Zu- / Abgang | F4: Lagerbestand ist | G4: Bewegung Einlagerung | H4: Bewegung Auslagerung | J4: Summe Bewegungen | K4: EB-Nummer(n)
F6: =SUM(D:D)+F3 -> 208 | G6: =SUM(B:B) -> 208 | H6: =SUM(C:C) -> 0 | J6: =SUM(G6:H6) -> 208
A7: 42682 | B7: 40 | D7: =B7-C7 -> 40 | K7: 469387, 471423, 471424, 471425, 471426, 471427, 471428, 469381, 469382, 469383, 469384, 469385, 469386, 471325, 471326, 471327, 471328, 471329, 471330, 471413, 471414, 471415, 471416, 471417, 471418, 471419, 471420, 471421, 471422, 468400, 468401, 468402, 468403, 469861, 469862, 469863, 469864, 469865, 469866, 469867
A8: 42683 | B8: 58 | D8: =B8-C8 -> 58 | K8: 411219, 467551, 467552, 467553, 467554, 456633, 456634, 467365, 467366, 467367, 467369, 468965, 468966, 468967, 468968, 469955, 469956, 469957, 469958, 469959, 469960, 469961, 469962, 469963, 469964, 469965, 469966, 469967, 469968, 469969, 469970, 469971, 469972, 416989, 435089, 435122, 448095, 449589, 449590, 449591, 449592, 449593, 449594, 449595, 449596, 449597, 449598, 466984, 466985, 466986, 363722, 363723, 363724, 363725, 363726, 363727, 636728, 363729
A9: 42684 | B9: 55 | D9: =B9-C9 -> 55 | K9: 373324, 373325, 373326, 418778, 418779, 422536, 428126, 428127, 428128, 428129, 428130, 415147, 415148, 415149, 415150, 469538, 469539, 469540, 469541, 469542, 469543, 416795, 418775, 418776, 418777, 469547, 469548, 469549, 411727, 472332, 472333, 472334, 472335, 472336, 472337, 472338, 472339, 469842, 469843, 469844, 469845, 469846, 469847, 469848, 469849, 469850, 404327, 443412, 443413, 443414, 443415, 402096, 415512, 415513, 415514
A10: 42689 | B10: 55 | D10: =B10-C10 -> 55 | K10: 439326, 458556, 467712, 467715, 467716, 462178, 439228, 448452, 468485, 466813, 431527, 463265, 463707, 463709, 463713, 426168, 431956, 448164, 453003, 441385, 461826, 461827, 460805, 431519, 426170, 441376, 417714, 470910, 470911, 470912, 470913, 470914, 470915, 470916, 444963, 400696, 400697, 416469, 407965, 472255, 472256, 472257, 472258, 472259, 417717, 417718, 417719, 402733, 415156, 472811, 472812, 472813, 472814, 472815, 472816
A11: 42689 | B11: 0 | C11: 0 | D11: =B11-C11 -> 0 | K11: 8 reservierte Plätze für ROTEXMEDICA: Regal C / Fach 4-5-6-7 C13,12,11,10 / C31 / C75,74,73
D12: =B12-C12 -> 0
D13: =B13-C13 -> 0
D14: =B14-C14 -> 0
D15: =B15-C15 -> 0
D16: =B16-C16 -> 0
D17: =B17-C17 -> 0
D18: =B18-C18 -> 0
D19: =B19-C19 -> 0
D20: =B20-C20 -> 0
D21: =B21-C21 -> 0
D22: =B22-C22 -> 0
D23: =B23-C23 -> 0
... D49: =B49-C49 -> 0

Sheet 12.16
A1: Rotexmedica Lager
F2: Übertrag aus Vormonat:
F3: ='11.16'!F6 -> 208
A4: Datum | B4: Ein- lagerung | C4: Aus- lagerung | D4: Zu- / Abgang | F4: Lagerbestand ist | G4: Bewegung Einlagerung | H4: Bewegung Auslagerung | J4: Summe Bewegungen | K4: EB-Nummer(n)
F6: =SUM(D:D)+F3 -> 196 | G6: =SUM(B:B) -> 0 | H6: =SUM(C:C) -> 12 | J6: =SUM(G6:H6) -> 12
A7: 42716 | B7: 0 | C7: 5 | D7: =B7-C7 -> -5 | K7: 472255, 472256, 472257, 472258, 472259
A8: 42732 | B8: 0 | C8: 7 | D8: =B8-C8 -> -7 | K8: 469381, 469382, 469383, 469384, 469385, 469386, 469387
D9: =B9-C9 -> 0
D10: =B10-C10 -> 0
D11: =B11-C11 -> 0
D12: =B12-C12 -> 0
D13: =B13-C13 -> 0
D14: =B14-C14 -> 0
D15: =B15-C15 -> 0
D16: =B16-C16 -> 0
D17: =B17-C17 -> 0
D18: =B18-C18 -> 0
D19: =B19-C19 -> 0
D20: =B20-C20 -> 0
... D44: =B44-C44 -> 0

Sheet 01.17
A1: Rotexmedica Lager
F2: Übertrag aus Vormonat:
F3: ='12.16'!F6 -> 196
A4: Datum | B4: Ein- lagerung | C4: Aus- lagerung | D4: Zu- / Abgang | F4: Lagerbestand ist | G4: Bewegung Einlagerung | H4: Bewegung Auslagerung | J4: Summe Bewegungen | K4: EB-Nummer(n)
L5: Traffic Bewegungen : Kontingent
F6: =SUM(D:D)+F3 -> 165 | G6: =SUM(B:B) -> 10 | H6: =SUM(C:C) -> 41 | J6: =SUM(G6:H6) -> 51 | L6: =J6/F6 -> 0.30909091
A7: 42739 | B7: 0 | C7: 8 | D7: =B7-C7 -> -8 | K7: 468965, 468966, 468967, 468968, 472332, 472333, 472335
A8: 42740 | B8: 0 | C8: 1 | D8: =B8-C8 -> -1 | K8: 448095
A9: 42748 | B9: 0 | C9: 3 | D9: =B9-C9 -> -3 | K9: 472337, 472338, 472339
A10: 42752 | B10: 0 | C10: 7 | D10: =B10-C10 -> -7 | K10: 472336, 471413, 471414, 471415, 471416, 471417, 471418
A11: 42761 | B11: 0 | C11: 4 | D11: =B11-C11 -> -4 | K11: 472811, 472812, 472813, 428126
A12: 42762 | B12: 10 | C12: 0 | D12: =B12-C12 -> 10 | K12: 476805, 476806, 476807, 476808, 476809, 476810, 476811, 476812, 476813, 476814
A13: 42766 | B13: 0 | C13: 18 | D13: =B13-C13 -> -18 | K13: 469955, 469956, 469957, 469958, 469959, 469960, 469961, 469962, 469963, 469964, 469965, 469966, 469967, 469968, 469969, 469970, 469971, 469972
D14: =B14-C14 -> 0
D15: =B15-C15 -> 0
D16: =B16-C16 -> 0
D17: =B17-C17 -> 0
D18: =B18-C18 -> 0
D19: =B19-C19 -> 0
D20: =B20-C20 -> 0
D21: =B21-C21 -> 0
D22: =B22-C22 -> 0
D23: =B23-C23 -> 0
D24: =B24-C24 -> 0
D25: =B25-C25 -> 0
... D44: =B44-C44 -> 0

Sheet 02.17
A1: Rotexmedica Lager
F2: Übertrag aus Vormonat:
F3: ='01.17'!F6 -> 165
A4: Datum | B4: Ein- lagerung | C4: Aus- lagerung | D4: Zu- / Abgang | F4: Lagerbestand ist | G4: Bewegung Einlagerung | H4: Bewegung Auslagerung | J4: Summe Bewegungen | K4: EB-Nummer(n)
L5: Traffic Bewegungen : Kontingent
F6: =SUM(D:D)+F3 -> 199 | G6: =SUM(B:B) -> 70 | H6: =SUM(C:C) -> 36 | J6: =SUM(G6:H6) -> 106 | L6: =J6/F6 -> 0.53266332
A7: 42767 | B7: 1 | C7: 0 | D7: =B7-C7 -> 1 | K7: Lösemittelentsorgungskanister | L7: Abgeholt und eingelagert nach Rg.Schluss am 31.01.17
A8: 42772 | B8: 16 | C8: 0 | D8: =B8-C8 -> 16 | K8: 477377, 477378, 477379, 477380, 477381, 477382, 477383, 477384, 477385, 477386, 477387, 477388, 477389, 477390, 477391, 477392
A9: 42774 | B9: 0 | C9: 7 | D9: =B9-C9 -> -7 | K9: 470910, 470911, 470912, 470913, 470914, 470915, 470916
A10: 42781 | B10: 1 | C10: 10 | D10: =B10-C10 -> -9 | K10: 471325, 471326, 471327, 471328, 471329, 471330, 418775, 418777, 441376, 466813 (davon nur ein Bulk = 1 Paket)
A11: 42782 | B11: 0 | C11: 9 | D11: =B11-C11 -> -9 | K11: 469482, 469843, 469844, 469845, 469846, 469847, 469848, 469849, 469850 | L11: 469482 wurde telef. nachgefordert und mit der 2. Tour geliefert!
A12: 42782 | B12: 13 | C12: 0 | D12: =B12-C12 -> 13 | K12: 477554, 477555, 477556, 477557, 477558, 477562, 477563, 477564,477565, 477566, 477567, 477568, 477569
A13: 42788 | B13: 17 | C13: 0 | D13: =B13-C13 -> 17 | K13: 450797, 450798, 450800, 457463, 457464, 457465, 468395, 468396, 468397, 468398, 468399, 472412, 472413, 476270, 476271, 476272, 474889
A14: 42793 | B14: 0 | C14: 10 | D14: =B14-C14 -> -10 | K14: 476805, 476806, 476807, 476808, 476809, 476810, 476811, 476812, 476813, 476814 | L14: Abruf telefonisch Thomas Zeh
A15: 42793 | B15: 22 | C15: 0 | D15: =B15-C15 -> 22 | K15: 478662, 478663, 478664, 478665, 478666, 478667, 478668, 478669, 478670, 478671, 478672, 478673, 478674, 478675, 478676, 478677, 478678, 478679, 478680, 478681, 478682, 478683
D16: =B16-C16 -> 0
D17: =B17-C17 -> 0
D18: =B18-C18 -> 0
D19: =B19-C19 -> 0
D20: =B20-C20 -> 0
D21: =B21-C21 -> 0
D22: =B22-C22 -> 0
D23: =B23-C23 -> 0
D24: =B24-C24 -> 0
D25: =B25-C25 -> 0
D26: =B26-C26 -> 0
D27: =B27-C27 -> 0
... D44: =B44-C44 -> 0

Sheet 03.17
A1: Rotexmedica Lager | J1: Kontingent: | K1: 252
F2: Übertrag aus Vormonat: | J2: Verfügbar: | K2: =K1-F6 -> 27
F3: ='02.17'!F6 -> 199
A4: Datum | B4: Ein- lagerung | C4: Aus- lagerung | D4: Zu- / Abgang | F4: Lagerbestand ist | G4: Bewegung Einlagerung | H4: Bewegung Auslagerung | J4: Summe Bewegungen | K4: EB-Nummer(n)
L5: Traffic Bewegungen : Kontingent
F6: =SUM(D:D)+F3 -> 225 | G6: =SUM(B:B) -> 58 | H6: =SUM(C:C) -> 32 | J6: =SUM(G6:H6) -> 90 | L6: =J6/K1 -> 0.35714286
A7: 42796 | B7: 0 | C7: 3 | D7: =B7-C7 -> -3 | K7: 471419, 471420, 471421
A8: 42802 | B8: 27 | C8: 0 | D8: =B8-C8 -> 27 | K8: 457925 (+457696+457970+457971+457972+457973=Stapel1) 457974 (+457976+457977+457978+457980+457981=Stapel2) 457982 (+457983+457984+457985+457986+457987=Stapel3) 479307, 479308, 479309, 479810, 399339, 448256, 462771, 462772, 462773VS, 477039, 456180, 439506, 465539VS, 471862, 471863, 471867, 471868, 471869, 471870, 459742, 459743VS, 459744, 447579, 448261 | L8: Lager-Erweiterung ab heute auf 252 Plätze
A9: 42811 | B9: 0 | C9: 24 | D9: =B9-C9 -> -24 | K9: 363723, 363724, 415514, 471422, 471423, 471424, 471425, 471426, 477562, 477563 477564, 428127, 428128, 477377, 477378, 477379, 477380, 477381, 477382, 472814 472815, 472816 Bitte einen vollen Karton von der EB 399339. und eb0Lösemittelentsorgungskanister mit den leeren Kanistern.
A10: 42811 | B10: 1 | C10: 0 | D10: =B10-C10 -> 1 | K10: 399339 (Rest:3 Krt)
A11: 42811 | B11: 0 | C11: 1 | D11: =B11-C11 -> -1 | K11: 463707
A12: 42811 | B12: 0 | C12: 1 | D12: =B12-C12 -> -1 | K12: 458556
A13: 42811 | B13: 30 | C13: 0 | D13: =B13-C13 -> 30 | K13: 445232, 416424, 420039, 421352, 475878, 373322, 373323, 452407, 460962, 476707, 476708, 476709, 476710, 476711, 469090, 468041, 469535, 469536, 469537, 449741, 468242, 469969, 469970, 469971, 469972, 472044, 472045, 437052, 447694, 479221
A14: 42822 | B14: 0 | C14: 3 | D14: =B14-C14 -> -3 | K14: 467712, 467715, 467716, Fahrkorb
D15: =B15-C15 -> 0
D16: =B16-C16 -> 0
D17: =B17-C17 -> 0
D18: =B18-C18 -> 0
D19: =B19-C19 -> 0
D20: =B20-C20 -> 0
D21: =B21-C21 -> 0
D22: =B22-C22 -> 0
D23: =B23-C23 -> 0
D24: =B24-C24 -> 0
D25: =B25-C25 -> 0
D26: =B26-C26 -> 0
... D44: =B44-C44 -> 0

Sheet 04.17
A1: Rotexmedica Lager | J1: Kontingent: | K1: 252
F2: Übertrag aus Vormonat: | J2: Verfügbar: | K2: =K1-F6 -> 19
F3: ='03.17'!F6 -> 225
A4: Datum | B4: Ein- lagerung | C4: Aus- lagerung | D4: Zu- / Abgang | F4: Lagerbestand ist | G4: Bewegung Einlagerung | H4: Bewegung Auslagerung | J4: Summe Bewegungen | K4: EB-Nummer(n)
L5: Traffic Bewegungen : Kontingent
F6: =SUM(D:D)+F3 -> 233 | G6: =SUM(B:B) -> 42 | H6: =SUM(C:C) -> 34 | J6: =SUM(G6:H6) -> 76 | L6: =J6/K1 -> 0.3015873
A7: 42828 | B7: 4 | C7: 0 | D7: =B7-C7 -> 4 | K7: 415514, 363724, 363723, Arbeitskorb
A8: 42835 | B8: 0 | C8: 11 | D8: =B8-C8 -> -11 | K8: 441385, 462178, 471427, 471428, 478662, 478663, 478664, 469969, 469970, 469971, 469972
A9: 42835 | B9: 28 | C9: 0 | D9: =B9-C9 -> 28 | K9: 481583, 481584, 481585, 481586, 481587, 481588, 481589, 481590, 481591, 481592, 481593, 481594, 481595, 481596, 481597, 481598, 481599, 481600, 481601, 481602, 481603, 481604, 481605, 481606, 481607, 481608, 481609, 481610 | L9: Direkt-Anlieferung i.A. Rotex per Container. Papiere wurden bei Rotex gemacht.
A10: 42846 | B10: 0 | C10: 10 | D10: =B10-C10 -> -10 | K10: 477383, 477384, 477385, 477386, 477387, 477388, 477389, 477390, 477391, 477392
A11: 42846 | B11: 0 | C11: 1 | D11: =B11-C11 -> -1 | K11: 411219
A12: 42851 | B12: 0 | C12: 12 | D12: =B12-C12 -> -12 | K12: 478665, 478666, 478667, 478668, 471862, 471863, 477565, 477566, 472044, 472045, 456633, 456634
A13: 42851 | B13: 10 | C13: 0 | D13: =B13-C13 -> 10 | K13: 482500, 482501, 482502, 482503, 482504, 482505, 482506, 482507, 482508, 482509
D14: =B14-C14 -> 0
D15: =B15-C15 -> 0
D16: =B16-C16 -> 0
D17: =B17-C17 -> 0
D18: =B18-C18 -> 0
D19: =B19-C19 -> 0
D20: =B20-C20 -> 0
D21: =B21-C21 -> 0
D22: =B22-C22 -> 0
D23: =B23-C23 -> 0
D24: =B24-C24 -> 0
D25: =B25-C25 -> 0
... D44: =B44-C44 -> 0

Sheet 05.17
A1: Rotexmedica Lager | J1: Kontingent: | K1: 252
F2: Übertrag aus Vormonat: | J2: Verfügbar: | K2: =K1-F6 -> 71
F3: ='04.17'!F6 -> 233
A4: Datum | B4: Ein- lagerung | C4: Aus- lagerung | D4: Zu- / Abgang | F4: Lagerbestand ist | G4: Bewegung Einlagerung | H4: Bewegung Auslagerung | J4: Summe Bewegungen | K4: EB-Nummer(n)
L5: Traffic Bewegungen : Kontingent
F6: =SUM(D:D)+F3 -> 181 | G6: =SUM(B:B) -> 48 | H6: =SUM(C:C) -> 100 | J6: =SUM(G6:H6) -> 148 | L6: =J6/K1 -> 0.58730159
A7: 42857 | B7: 0 | C7: 6 | D7: =B7-C7 -> -6 | K7: 468041, 469090, 477567, 477568, 477569, 469535
A8: 42857 | B8: 8 | C8: 0 | D8: =B8-C8 -> 8 | K8: 482761, 482762, 482763, 482764, 482765, 482766, 482767, 482768
A9: 42858 | B9: 0 | C9: 13 | D9: =B9-C9 -> -13 | K9: 417717, 417718, 417719, 402733, 416469, 415147, 415148, 415149, 415150, 400696, 400697, 407965, 417714 | L9: Umfuhr Vernichtung
A10: 42858 | B10: 0 | C10: 26 | D10: =B10-C10 -> -26 | K10: 476707, 476708, 476709, 476710, 476711, 447964, 479221, 445232, 452407, 460962, 468395, 468396, 468397, 468398, 468399, 468400, 468401, 468402, 468403, 469861, 469862, 469863, 469864, 469865, 469866, 469867
A11: 42863 | B11: 24 | C11: 0 | D11: =B11-C11 -> 24 | K11: 481813, 481814, 481815, 481816, 481817, 481818, 481819, 481820, 481713, 481714, 481715, 481716, 481717, 481718, 481719, 481720, 481721, 481722, 481723, 481724, 481725, 481726, 481727, 481728
A12: 42864 | B12: 0 | C12: 14 | D12: =B12-C12 -> -14 | K12: 468485, 472412, 472413, 466813, 482500, 482501, 482502 , 482503, 482504, 482505, 482506, 482507, 482508, 482509
A13: 42864 | B13: 16 | C13: 0 | D13: =B13-C13 -> 16 | K13: 480035, 480036, 480037, 480038, 480039, 479184, 479185, 480453, 480344, 480345, 457992, 471670, 475830, 479876, 480277, 470113
A14: 42872 | B14: 0 | C14: 19 | D14: =B14-C14 -> -19 | K14: 481721, 481722, 481723, 481724, 481725, 481726, 481727, 481728, 478669, 478670, 478671, 478672, 478673, 478674, 482761, 482762, 477554, 448452, 447579
A15: 42884 | B15: 0 | C15: 4 | D15: =B15-C15 -> -4 | K15: 465539, 469547, 469548, 469549
A16: 42885 | B16: 0 | C16: 18 | D16: =B16-C16 -> -18 | K16: 481593, 481594, 481595, 481596, 481597, 481598, 481599, 481600, 481601, 481602, 481603, 481604, 481605, 481606, 481607, 481608, 481609, 481610
D17: =B17-C17 -> 0
D18: =B18-C18 -> 0
D19: =B19-C19 -> 0
D20: =B20-C20 -> 0
D21: =B21-C21 -> 0
D22: =B22-C22 -> 0
D23: =B23-C23 -> 0
D24: =B24-C24 -> 0
D25: =B25-C25 -> 0
D26: =B26-C26 -> 0
D27: =B27-C27 -> 0
D28: =B28-C28 -> 0
... D44: =B44-C44 -> 0

Sheet 06.17
A1: Rotexmedica Lager | J1: Kontingent: | K1: 252
F2: Übertrag aus Vormonat: | J2: Verfügbar: | K2: =K1-F6 -> 9
F3: ='05.17'!F6 -> 181
A4: Datum | B4: Ein- lagerung | C4: Aus- lagerung | D4: Zu- / Abgang | F4: Lagerbestand ist | G4: Bewegung Einlagerung | H4: Bewegung Auslagerung | J4: Summe Bewegungen | K4: EB-Nummer(n)
L5: Traffic Bewegungen : Kontingent
F6: =SUM(D:D)+F3 -> 243 | G6: =SUM(B:B) -> 86 | H6: =SUM(C:C) -> 24 | J6: =SUM(G6:H6) -> 110 | L6: =J6/K1 -> 0.43650794
A7: 42887 | B7: 0 | C7: 1 | D7: =B7-C7 -> -1 | K7: eb0 Arbeitskorb
A8: 42894 | B8: 1 | C8: 1 | D8: =B8-C8 -> 0 | K8: eb0 Arbeitskorb abgeholt für Datalogger, danach direkt wieder zurück
A9: 42907 | B9: 0 | C9: 17 | D9: =B9-C9 -> -17 | K9: 481713, 481714, 481715, 481716, 480035, 480036, 480277, 418778, 418779, 478675, 478676, 478677, 478678, 482763, 482764, 482765, 477555
A10: 42907 | B10: 35 | C10: 0 | D10: =B10-C10 -> 35 | K10: 485323, 485324, 485325, 485326, 485327, 485328, 485329, 485330, 485331, 483870, 483871, 483872, 483865, 483866, 483867, 483868, 483869, GrKis1, GrKis3, GrKis3, 485309, 485310, 485311, 485312, 485313, 485314, 469547, 469548, 469549, 485566, 485567, 485568, 485569, 485570, ArbKor
A11: 42913 | B11: 0 | C11: 4 | D11: =B11-C11 -> -4 | K11: 481583, 481584, 481585, 481586
A12: 42914 | B12: 0 | C12: 1 | D12: =B12-C12 -> -1 | K12: 470113
A13: 42914 | B13: 28 | C13: 0 | D13: =B13-C13 -> 28 | K13: 486242, 486243, 486244, 486245, 486246, 486247, 486248, 486249, 486250, 486251, 486252, 486253, 486254, 486255, 486256, 486257, 486258, 486259, 486260, 486261, 486262, 486263, 486270, 486271, 486272, 486273, 486274, 486275
A14: 42914 | B14: 22 | C14: 0 | D14: =B14-C14 -> 22 | K14: 486283, 486284, 486285, 486286, 486287, 486288, 486289, 486290, 486291, 486292, 486293, 486294, 486295, 486296, 486297, 486298, 486299, 486300, 486301, 486302, 486303, 486304
D15: =B15-C15 -> 0
D16: =B16-C16 -> 0
D17: =B17-C17 -> 0
D18: =B18-C18 -> 0
D19: =B19-C19 -> 0
D20: =B20-C20 -> 0
D21: =B21-C21 -> 0
D22: =B22-C22 -> 0
D23: =B23-C23 -> 0
D24: =B24-C24 -> 0
D25: =B25-C25 -> 0
D26: =B26-C26 -> 0
... D44: =B44-C44 -> 0

Sheet 07.17
A1: Rotexmedica Lager | J1: Kontingent: | K1: 252
F2: Übertrag aus Vormonat: | J2: Verfügbar: | K2: =K1-F6 -> 9
F3: ='06.17'!F6 -> 243
A4: Datum | B4: Ein- lagerung | C4: Aus- lagerung | D4: Zu- / Abgang | F4: Lagerbestand ist | G4: Bewegung Einlagerung | H4: Bewegung Auslagerung | J4: Summe Bewegungen | K4: EB-Nummer(n)
L5: Traffic Bewegungen : Kontingent
F6: =SUM(D:D)+F3 -> 243 | G6: =SUM(B:B) -> 1 | H6: =SUM(C:C) -> 1 | J6: =SUM(G6:H6) -> 2 | L6: =J6/K1 -> 0.0079365079
A7: 42919 | B7: 1 | C7: 1 | D7: =B7-C7 -> 0 | K7: 363722 Teilentnahme
D8: =B8-C8 -> 0
D9: =B9-C9 -> 0
D10: =B10-C10 -> 0
D11: =B11-C11 -> 0
D12: =B12-C12 -> 0
D13: =B13-C13 -> 0
D14: =B14-C14 -> 0
D15: =B15-C15 -> 0
D16: =B16-C16 -> 0
D17: =B17-C17 -> 0
D18: =B18-C18 -> 0
D19: =B19-C19 -> 0
... D44: =B44-C44 -> 0

Sheet 08.17
A1: Rotexmedica Lager | J1: Kontingent: | K1: 252
F2: Übertrag aus Vormonat: | J2: Verfügbar: | K2: =K1-F6 -> 11
F3: ='07.17'!F3 -> 243
A4: Datum | B4: Ein- lagerung | C4: Aus- lagerung | D4: Zu- / Abgang | F4: Lagerbestand ist | G4: Bewegung Einlagerung | H4: Bewegung Auslagerung | J4: Summe Bewegungen | K4: EB-Nummer(n)
L5: Traffic Bewegungen : Kontingent
F6: =SUM(D:D)+F3 -> 241 | G6: =SUM(B:B) -> 41 | H6: =SUM(C:C) -> 43 | J6: =SUM(G6:H6) -> 84 | L6: =J6/K1 -> 0.33333333
A7: 42956 | B7: 1 | C7: 1 | D7: =B7-C7 -> 0 | K7: 431519 Teilentnahme (26 Kartons)
A8: 42956 | B8: 0 | C8: 1 | D8: =B8-C8 -> -1 | K8: 439228
A9: 42962 | B9: 0 | C9: 2 | D9: =B9-C9 -> -2 | K9: 475830, 479876
A10: 42965 | B10: 0 | C10: 32 | D10: =B10-C10 -> -32 | K10: 457925 (+457696+457970+457971+457972+457973=Stapel1) 457974 (+457976+457977+457978+457980+457981=Stapel2) 457982 (+457983+457984+457985+457986+457987=Stapel3) 479184, 479185, 459742, 478679, 478680, 478681, 478682, 482766, 482767, 482768, 485323, 477556, 477557, 477558, 404327, 443412, 443413, 443414, 443415, 449589, 449590, 449591, 449592, 449593, 467365, 467366, 485566, 485567, 485568
A11: 42965 | B11: 40 | C11: 0 | D11: =B11-C11 -> 40 | K11: 488594, 488595, 488596, 488603, 488604, 488605, 488606, 488607, 488608, 488609, 488610, 488611, 488612, 488597, 488598, 488621, 488622, 488623, 488624, 488625, 488626, 487804, 487805, 487806, 487807, 487808, 487758, 487759, 487760, 487761, 487672, 488655, 488656, 488657, 488658, 488659, 488660, 488661, 488662, 488278
A12: 42971 | B12: 0 | C12: 1 | D12: =B12-C12 -> -1 | K12: 475878
A13: 42976 | B13: 0 | C13: 6 | D13: =B13-C13 -> -6 | K13: 481587, 481588, 481589, 481590, 481591, 481592
D14: =B14-C14 -> 0
D15: =B15-C15 -> 0
D16: =B16-C16 -> 0
D17: =B17-C17 -> 0
D18: =B18-C18 -> 0
D19: =B19-C19 -> 0
D20: =B20-C20 -> 0
D21: =B21-C21 -> 0
D22: =B22-C22 -> 0
D23: =B23-C23 -> 0
D24: =B24-C24 -> 0
D25: =B25-C25 -> 0
... D44: =B44-C44 -> 0

Sheet 09.17
A1: Rotexmedica Lager | J1: Kontingent: | K1: =252+12 -> 264
F2: Übertrag aus Vormonat: | J2: Verfügbar: | K2: =K1-F6 -> 16
F3: ='08.17'!F6 -> 241
A4: Datum | B4: Ein- lagerung | C4: Aus- lagerung | D4: Zu- / Abgang | F4: Lagerbestand ist | G4: Bewegung Einlagerung | H4: Bewegung Auslagerung | J4: Summe Bewegungen | K4: EB-Nummer(n)
L5: Traffic Bewegungen : Kontingent
F6: =SUM(D:D)+F3 -> 248 | G6: =SUM(B:B) -> 66 | H6: =SUM(C:C) -> 59 | J6: =SUM(G6:H6) -> 125 | L6: =J6/K1 -> 0.47348485
A7: 42982 | B7: 0 | C7: 1 | D7: =B7-C7 -> -1 | K7: 428130
A8: 42990 | B8: 0 | C8: 3 | D8: =B8-C8 -> -3 | K8: 480038, 480039, 437052
A9: 42996 | B9: 0 | C9: 11 | D9: =B9-C9 -> -11 | K9: 480037, 488621, 488622, 488623, 488624, 488625, 488626, 488278, 488594, 488595, 488596
A10: 42996 | B10: 18 | C10: 0 | D10: =B10-C10 -> 18 | K10: 490232, 490233, 490234, 490235, 490236, 490237, 490238, 490239, 490240, 490249, 490250, 490251, 490252, 490253, 490254, 490255, 490256, 490257
A11: 42997 | B11: 13 | C11: 0 | D11: =B11-C11 -> 13 | K11: 490336, 490337, 490338, 490339, 490340, 490341, 490342, 490343, 490344, 490345, 490346, 490347, 490348 | L11: Lager-Erweiterung ab heute auf 264 Plätze
A12: 43005 | B12: 0 | C12: 43 | D12: =B12-C12 -> -43 | K12: 481717, 481718, 481719, 481720, 481813, 486242, 486243, 486244, 486245, 486246, 486247, 486248, 486249, 486250, 486251, 487804, 487805, 487806, 487807, 487808, 480453, 478683, 486283, 486284, 486285, 486286, 486287, 471867, 485324, 485325, 485326, 485327, 486270, 486271, 488597, 488598, 485569, 485570, 480344, 480345, 483865, 483866, 483867
A13: 43006 | B13: 35 | C13: 0 | D13: =B13-C13 -> 35 | K13: 489891, 489892, 489893, 482253, 490244, 490245, 490246, 490247, 440879, 440881, 485515, 489572, 489580, 489581, 489584, 489585, 489589, 489591, 489596, 490064, 490065, 490066, 490067, 490068, 490069, 490072, 490074, 490075, 490076, 490077, 490080, 490081, 490082, 490083, 490302
A14: 43006 | B14: 0 | C14: 1 | D14: =B14-C14 -> -1 | K14: eb0ArbKor
D15: =B15-C15 -> 0
D16: =B16-C16 -> 0
D17: =B17-C17 -> 0
D18: =B18-C18 -> 0
D19: =B19-C19 -> 0
D20: =B20-C20 -> 0
D21: =B21-C21 -> 0
D22: =B22-C22 -> 0
D23: =B23-C23 -> 0
D24: =B24-C24 -> 0
D25: =B25-C25 -> 0
D26: =B26-C26 -> 0
... D44: =B44-C44 -> 0

Sheet 10.17
A1: Rotexmedica Lager | J1: Kontingent: | K1: =264+12 -> 276
F2: Übertrag aus Vormonat: | J2: Verfügbar: | K2: =K1-F6 -> 23
F3: ='09.17'!F6 -> 248
A4: Datum | B4: Ein- lagerung | C4: Aus- lagerung | D4: Zu- / Abgang | F4: Lagerbestand ist | G4: Bewegung Einlagerung | H4: Bewegung Auslagerung | J4: Summe Bewegungen | K4: EB-Nummer(n)
L5: Traffic Bewegungen : Kontingent
F6: =SUM(D:D)+F3 -> 253 | G6: =SUM(B:B) -> 38 | H6: =SUM(C:C) -> 33 | J6: =SUM(G6:H6) -> 71 | L6: =J6/K1 -> 0.25724638
A7: 43012 | B7: 1 | C7: 0 | D7: =B7-C7 -> 1 | K7: eb0ArbKor
A8: 43018 | B8: 0 | C8: 1 | D8: =B8-C8 -> -1 | K8: 490336 | L8: Lager-Erweiterung ab heute auf 276 Plätze
A9: 43018 | B9: 22 | C9: 0 | D9: =B9-C9 -> 22 | K9: 491572, 491573, 491574, 491575, 491576, 491577, 491578, 491579, 491580, 491581, 491582, 491583, 491497, 491498, 491499, 491500, 491501, 491502, 491503, 491504, 491505, 491506
A10: 43024 | B10: 0 | C10: 5 | D10: =B10-C10 -> -5 | K10: 485515, 489572, 486288, 486289, 486290
A11: 43024 | B11: 7 | C11: 0 | D11: =B11-C11 -> 7 | K11: 491997, 491998, 491999, 492000, 492001, 492002, 492003
A12: 43032 | B12: 0 | C12: 27 | D12: =B12-C12 -> -27 | K12: 488603, 488604, 488605, 488606, 488607, 488608, 485309, 485310, 483869, 483870, 483871 ,490232, 490233, 490234, 490235, 490236, 490249, 490250, 490251, 490252, 490253, 490244, 490245, 490246, 490247, 489580, 489581
A13: 43032 | B13: 8 | C13: 0 | D13: =B13-C13 -> 8 | K13: 492519, 492520, 492521, 492522, 492523, 492524, 492525, 492526
D14: =B14-C14 -> 0
D15: =B15-C15 -> 0
D16: =B16-C16 -> 0
D17: =B17-C17 -> 0
D18: =B18-C18 -> 0
D19: =B19-C19 -> 0
D20: =B20-C20 -> 0
D21: =B21-C21 -> 0
D22: =B22-C22 -> 0
D23: =B23-C23 -> 0
D24: =B24-C24 -> 0
D25: =B25-C25 -> 0
... D44: =B44-C44 -> 0

Sheet 11.17
A1: Rotexmedica Lager | J1: Kontingent: | K1: =288+132 -> 420
F2: Übertrag aus Vormonat: | J2: Verfügbar: | K2: =K1-F6 -> 63
F3: ='10.17'!F6 -> 253
A4: Datum | B4: Ein- lagerung | C4: Aus- lagerung | D4: Zu- / Abgang | E4: Extra Handling | F4: Lagerbestand ist | G4: Bewegung Einlagerung | H4: Bewegung Auslagerung | J4: Summe Bewegungen | K4: EB-Nummer(n)
L5: Traffic Bewegungen : Kontingent
F6: =SUM(D:D)+F3 -> 357 | G6: =SUM(B:B) -> 163 | H6: =SUM(C:C) -> 59 | J6: =SUM(G6:H6)+SUM(E:E) -> 240 | L6: =J6/K1 -> 0.57142857
A7: 43046 | B7: 0 | C7: 12 | D7: =B7-C7 -> -12 | K7: 490337 bis 490348 = 12 Pal. Auslagern, jeweils 62 Vials entnehmen, in Karton packen, beschriften, auf EWP verpacken
A8: 43047 | B8: 12 | C8: 0 | D8: =B8-C8 -> 12 | K8: 490337 bis 490348 = 12 Pal. Einlagern
A9: 43047 | B9: 0 | C9: 1 | D9: =B9-C9 -> -1 | K9: eb0ArbKor
A10: 43048 | B10: 26 | C10: 0 | D10: =B10-C10 -> 26 | K10: 493451, 493452, 493453, 493454, 493455, 493456, 493457, 493458, 493459, 493460, 493461, 493462, 493463, 493464, 493465, 493466, 493467, 493468, 493469, 493470, 493471, 493472, 493473, 493474, 493475, 496476 | L10: Lager-Erweiterung ab heute auf 288 Plätze
A11: 43052 | B11: 27 | C11: 0 | D11: =B11-C11 -> 27 | K11: 493719, 493420, 493721, 493722, 493723, 493724, 493725, 493726, 493727, 493728, 493729, 493730, 493731, 493732, 493733, 493734, 493735, 493736, 493737, 493738, 493739, 493740, 493741, 493742, 493743, 493744, ArbKor | L11: Lager-Erweiterung ab heute (13.11.2017) um 132 auf 420 Plätze (siehe email, Ronny Wulff) es fehlen: 493743 + 473744, dafür 493722 dreimal vorhanden (13.11.17) -- wurde am 14.11.17 korrigiert! MK
A12: 43053 | B12: 9 | C12: 0 | D12: =B12-C12 -> 9 | K12: 493870, 493872, 493873, 493874, 493875, 493876, 493877, 493878, 493879
A13: 43054 | B13: 16 | C13: 0 | D13: =B13-C13 -> 16 | K13: 493957, 493958, 493959, 493960, 493961, 493962, 493963, 493964, 493965, 493966, 493967, 493968, 493969, 493970, 493971, 493972
A14: 43055 | B14: 0 | C14: 4 | D14: =B14-C14 -> -4 | K14: 490254, 490255, 490256, 490257
A15: 43056 | B15: 10 | C15: 0 | D15: =B15-C15 -> 10 | K15: 494074, 494075, 494076, 494077, 494078, 494079, 494080, 494081, 492471, 492472
A16: 43059 | B16: 0 | C16: 4 | D16: =B16-C16 -> -4 | K16: 486272, 486273, 486274, 486275
A17: 43061 | B17: 0 | C17: 3 | D17: =B17-C17 -> -3 | K17: 489891, 489892, 489893
A18: 43061 | B18: 19 | C18: 0 | D18: =B18-C18 -> 19 | K18: 000001, 000002, 000003, 000004, 000005, 000006, 000007, 000008, 000009, 000010, 000011, 000012, 000013, 000014, 000015, 000016, 000017, 494410, 494411
A19: 43061 | B19: 14 | C19: 0 | D19: =B19-C19 -> 14 | K19: 494444, 494445, 494446, 494447, 494448, 494449, 494450, 494451, 494452, 494453, 494454, 494455, 494456, 494457
A20: 43063 | B20: 0 | C20: 13 | D20: =B20-C20 -> -13 | K20: 493451, 493452, 493453, 493454, 493455, 493957, 493958, 493959, 493960, 493961, 493962, 493963, 493694
A21: 43066 | B21: 0 | C21: 0 | D21: =B21-C21 -> 0 | E21: 18 | K21: Handling Zwischenlager Block - Paletten labeln | L21: 35x Doppelpaletten eb0 (Fremdanlieferung) wird gedoppelt Eingelagert = 18 Pal.
A22: 43066 | B22: 0 | C22: 21 | D22: =B22-C22 -> -21 | K22: 449594, 449595, 449596, 449597, 449598, 459743, 459744, 486291, 486292, 486293, 486294, 489584, 489585, 489589, 489591, 491497, 491498, 491499, 492519, 492520, 492521
A23: 43067 | B23: 0 | C23: 1 | D23: =B23-C23 -> -1 | K23: 479307
A24: 43068 | B24: 12 | C24: 0 | D24: =B24-C24 -> 12 | K24: 494810, 494811, 494812, 494813, 494814, 494815, 494816, 494817, 000018A, 000018B, 000019A, 000019B
A25: 43068 | B25: 18 | C25: 0 | D25: =B25-C25 -> 18 | K25: 494736, 494947, 494948, 494949, 494950, 494951, 494952, 494953, 494954, 494955, 494956, 494957, 494958, 494959, 494960, 494961, 494962, 494963
D26: =B26-C26 -> 0
D27: =B27-C27 -> 0
D28: =B28-C28 -> 0
D29: =B29-C29 -> 0
D30: =B30-C30 -> 0
D31: =B31-C31 -> 0
D32: =B32-C32 -> 0
D33: =B33-C33 -> 0
D34: =B34-C34 -> 0
D35: =B35-C35 -> 0
D36: =B36-C36 -> 0
D37: =B37-C37 -> 0
... D44: =B44-C44 -> 0

Sheet 12.17
A1: Rotexmedica Lager | J1: Kontingent: | K1: =288+132 -> 420
F2: Übertrag aus Vormonat: | J2: Verfügbar: | K2: =K1-F6 -> 143
F3: ='11.17'!F6 -> 357
A4: Datum | B4: Ein- lagerung | C4: Aus- lagerung | D4: Zu- / Abgang | E4: Extra Handling | F4: Lagerbestand ist | G4: Bewegung Einlagerung | H4: Bewegung Auslagerung | J4: Summe Bewegungen | K4: EB-Nummer(n)
L5: Traffic Bewegungen : Kontingent
F6: =SUM(D:D)+F3 -> 277 | G6: =SUM(B:B) -> 27 | H6: =SUM(C:C) -> 107 | J6: =SUM(G6:H6)+SUM(E:E) -> 134 | L6: =J6/K1 -> 0.31904762
A7: 43070 | B7: 0 | C7: 9 | D7: =B7-C7 -> -9 | K7: 493965, 493966, 493465, 493466, 485328, 485329, 487758, 491997, 467367
A8: 43076 | B8: 0 | C8: 21 | D8: =B8-C8 -> -21 | K8: 494444, 494445, 494446, 494447, 494448, 489596, 490064, 490065, 490066, 493473, 493474, 493475, 493476, 486295, 486296, 486297, 493720, 493721, 493722, 493723, 491998
A9: 43081 | B9: 0 | C9: 23 | D9: =B9-C9 -> -23 | K9: 483868, 483872, 488655, 493467, 493468, 493469, 493470, 494449, 494450, 494451, 494452, 494453, 486298, 486299, 486300, 491500, 491501, 491502, 491503, 488609, 488610, 488611, 488612
A10: 43081 | B10: 6 | C10: 0 | D10: =B10-C10 -> 6 | K10: 495672, 495673, 495674, 495675, 495676, 495677
A11: 43083 | B11: 0 | C11: 5 | D11: =B11-C11 -> -5 | K11: 492522, 492523, 492524, 492525, 492526
A12: 43084 | B12: 21 | C12: 0 | D12: =B12-C12 -> 21 | K12: 000020, 000021, 000022, 000023, 000024, 000025, 000026, 000027, 000028, 000029, 000030, 000031, 000032, 000033, 000034, 000035, 000036, 000037, 000038, 000039, 000040
A13: 43087 | B13: 0 | C13: 41 | D13: =B13-C13 -> -41 | K13: 485311, 485312, 493967, 493968, 493969, 494454, 494455, 494456, 494457, 494074, 494075, 494076, 494077, 494078, 494079, 494080, 494081, 486301, 486302, 485330, 485331, 493872, 493873, 487759, 487760, 490339, 490340, 490341, 467369, 490240, 491572, 491573, 491574, 491575, 491576, 491577, 491578, 492472, 440881, 440879, 492471
A14: 43090 | B14: 0 | C14: 7 | D14: =B14-C14 -> -7 | K14: 485313, 485314, 469548, 469547, 491504, 491505, ArbKor
A15: 43098 | B15: 0 | C15: 1 | D15: =B15-C15 -> -1 | K15: 457463
D16: =B16-C16 -> 0
D17: =B17-C17 -> 0
D18: =B18-C18 -> 0
D19: =B19-C19 -> 0
D20: =B20-C20 -> 0
D21: =B21-C21 -> 0
D22: =B22-C22 -> 0
D23: =B23-C23 -> 0
D24: =B24-C24 -> 0
D25: =B25-C25 -> 0
D26: =B26-C26 -> 0
D27: =B27-C27 -> 0
... D44: =B44-C44 -> 0

Sheet 01.18
A1: Rotexmedica Lager | J1: Kontingent: | K1: =288+132+36 -> 456
F2: Übertrag aus Vormonat: | J2: Verfügbar: | K2: =K1-F6 -> 33
F3: ='12.17'!F6 -> 277
A4: Datum | B4: Ein- lagerung | C4: Aus- lagerung | D4: Zu- / Abgang | E4: Extra Handling | F4: Lagerbestand ist | G4: Bewegung Einlagerung | H4: Bewegung Auslagerung | J4: Summe Bewegungen | K4: EB-Nummer(n)
L5: Traffic Bewegungen : Kontingent
F6: =SUM(D:D)+F3 -> 423 | G6: =SUM(B:B) -> 252 | H6: =SUM(C:C) -> 106 | J6: =SUM(G6:H6)+SUM(E:E) -> 401 | L6: =J6/K1 -> 0.87938596
A7: 43103 | B7: 1 | C7: 17 | D7: =B7-C7 -> -16 | K7: 444963, 431956, 416424, 426168, 462771, 439326, 448261, 456180, 448256, 477039, 399339, 416795, 428129, 000022, 000023, 000024, 476272 (Teilentnahme!)
A8: 43103 | B8: 40 | C8: 0 | D8: =B8-C8 -> 40 | K8: 496598, 496599, 496600, 496601, 496602, 496603, 496604, 496605, 496607, 496608, 496609, 496610, 496611, 496612, 496613, 496614, 496615, 496616, 496618, 496619, 496620, 496621, 496622, 496623, 496624, 496625, 496626, 496627, 496628, 496629, 496630, 496632, 496633, 496635, 496636, 496637, 496638, 496639, 496671, ArbKor
A9: 43109 | B9: 0 | C9: 15 | D9: =B9-C9 -> -15 | K9: 494810, 494811, 494812, 494813, 494814, 494815, 494816, 494817, 493719, 493724, 493725, 493726, 493970, 493971, 493972
A10: 43109 | B10: 5 | C10: 0 | D10: =B10-C10 -> 5 | K10: 496846, 496847, 496848, 496849, 496850
A11: 43110 | B11: 15 | C11: 0 | D11: =B11-C11 -> 15 | K11: 497036, 497037, 497038, 497039, 497040, 497041, 497042, 497043, 459743, 459744, 487928, 481813, 479024, 492192, 479023
A12: 43112 | B12: 0 | C12: 7 | D12: =B12-C12 -> -7 | K12: 431527, 467551, 467552, 467553, 416989, 435089, 435122
A13: 43112 | B13: 0 | C13: 1 | D13: =B13-C13 -> -1 | K13: 20
A14: 43112 | B14: 18 | C14: 0 | D14: =B14-C14 -> 18 | K14: 497180, 497181, 497182, 497183, 497184, 497185, 497187, 497068, 497069 EUP def., 497071, 497073, 497144, 497145, 497146, 497147, 497148, 497188, 497074
A15: 43116 | B15: 0 | C15: 13 | D15: =B15-C15 -> -13 | K15: 493456, 493457, 493458, 493459, 493460, 493461, 493462, 493463, 491999, 492000, 491506, 486303, 486304
A16: 43116 | B16: 19 | C16: 0 | D16: =B16-C16 -> 19 | K16: 480148, 480822, 486080, 487851, 489447, 489448, 492102, 492103, 492104, 492105, 492107, 492108, 493016, 493017, 493018, 496524, 497379, 497380, ohneEB-Nr.
A17: 43117 | B17: 51 | C17: 0 | D17: =B17-C17 -> 51 | K17: 497480, 497481, 497482, 497483, 497484, 497485, 497553, 497554, 497555, 497556, 497557, 497486, 497494, 497495, 497496, 497497, 497498, 497501, 497502, 497503, 497504, 497505, 497506, 497507, 497508, 497509, 497510, 497511, 497512, 497513, 497514, 497515, 497516, 497517, 497518, 497519, 497520, 497521, 497522, 497523, 497524, 497525, 497526, 497527, 497528, 497529, 497530, 497531, 497532, 497533, 489224
A18: 43117 | B18: 0 | C18: 1 | D18: =B18-C18 -> -1 | K18: ohneEB-Nr.
A19: 43119 | B19: 0 | C19: 19 | D19: =B19-C19 -> -19 | K19: 000026, 493727, 493728, 493729, 493730, 493731, 493732, 493733, 493734, 493735, 493736, 493737, 493738, 493739, 493740, 493741, 493742, 493743, 493744
A20: 43119 | B20: 0 | C20: 10 | D20: =B20-C20 -> -10 | K20: 490068, 490069, 490072, 490074, 490075, 488656, 488657, 488658, 488659, 488660
A21: 43122 | B21: 0 | C21: 8 | D21: =B21-C21 -> -8 | K21: 494410, 494411, 497480, 490237, 490238, 490239, 491579, 479309
A22: 43122 | B22: 0 | C22: 0 | D22: =B22-C22 -> 0 | E22: 43 | K22: Handling Zwischenlager Block - Paletten labeln
A23: 43123 | B23: 70 | C23: 0 | D23: =B23-C23 -> 70 | K23: 497916, 497917, 497918, 497919, 497920, 497921, 497922, 497923, 497924, 497925, 497926, 497927, 497928, 497929, 497930, 497931, 497932, 497933, 497934, 497935, 497936, 497937, 497938, 497939, 497940, 497941, 497942, 497943, 497944, 497945, 497946, 497947, 497948, 497949, 497950, 497951, 497952, 497953, 497954, 497955, 497956, 497957, 497958, 497905, 497906, 497907, 497908, 497909, 497910, 497911, 498062, 498063, 498064, 498065, 498066, 498067, 498068, 498069, 498070, 498071, 498072, 498073, 498074, 498075, 498076, 498077, 498078, 498079, 498080, 498081
A24: 43124 | B24: 18 | C24: 0 | D24: =B24-C24 -> 18 | K24: 000026, 498096, 498097, 498098, 498099, 498100, 498101, 498102, 498150, 498151, 498152, 498153, 498154, 498155, 498156, 498157, 498158, 498159 | L24: Lager-Erweiterung ab heute auf 456 Plätze
A25: 43126 | B25: 0 | C25: 15 | D25: =B25-C25 -> -15 | K25: 496598, 496599, 496600, 496601, 491580, 491581, 490067, 490076, 493870, 493874, 493875, 494736, 494947, 457992, 471670
A26: 43130 | B26: 15 | C26: 0 | D26: =B26-C26 -> 15 | K26: 498362, 498363, 498364, 498365, 498366, 498367, 498368, 498369, 498370, 498371, 498372, 498373, 498375, 000041, 000042
D27: =B27-C27 -> 0
D28: =B28-C28 -> 0
D29: =B29-C29 -> 0
D30: =B30-C30 -> 0
D31: =B31-C31 -> 0
D32: =B32-C32 -> 0
D33: =B33-C33 -> 0
D34: =B34-C34 -> 0
D35: =B35-C35 -> 0
D36: =B36-C36 -> 0
D37: =B37-C37 -> 0
D38: =B38-C38 -> 0
... D44: =B44-C44 -> 0

Sheet 02.18
A1: Rotexmedica Lager | J1: Kontingent: | K1: =288+132+36+36 -> 492
F2: Übertrag aus Vormonat: | J2: Verfügbar: | K2: =K1-F6 -> 74
F3: ='01.18'!F6 -> 423
A4: Datum | B4: Ein- lagerung | C4: Aus- lagerung | D4: Zu- / Abgang | E4: Extra Handling | F4: Lagerbestand ist | G4: Bewegung Einlagerung | H4: Bewegung Auslagerung | J4: Summe Bewegungen | K4: EB-Nummer(n)
L5: Traffic Bewegungen : Kontingent
F6: =SUM(D:D)+F3 -> 418 | G6: =SUM(B:B) -> 123 | H6: =SUM(C:C) -> 128 | J6: =SUM(G6:H6)+SUM(E:E) -> 303 | L6: =J6/K1 -> 0.61585366
A7: 43132 | B7: 10 | C7: 0 | D7: =B7-C7 -> 10 | K7: 498507, 498508, 498509, 498510, 498511, 498512, 498513, 498514, 498515, 498516
A8: 43133 | B8: 0 | C8: 25 | D8: =B8-C8 -> -25 | K8: 497501, 497502, 497503, 497504, 497505, 497506, 497507, 497508, 497509, 497510, 497511, 497512, 497513, 497514, 498062, 498063, 494948, 494949, 494950, 496602, 496603, 496604, 490077, 490080, 490081
A9: 43136 | B9: 9 | C9: 9 | D9: =B9-C9 -> 0 | K9: QS zieht Paletten-Nr.: 0026, 0016, 0017, 0027, 0033, 0034, 0035, 0036, 0038
A10: 43137 | B10: 0 | C10: 8 | D10: =B10-C10 -> -8 | K10: 363722, 363723, 363724, 363725, 363726, 363727, 363728, 363729 | L10: zur Vernichtung
A11: 43137 | B11: 0 | C11: 0 | D11: =B11-C11 -> 0 | E11: 42 | K11: Handling Zwischenlager Block - Paletten labeln | L11: Lager-Erweiterung ab heute auf 492 Plätze
A12: 43137 | B12: 0 | C12: 0 | D12: =B12-C12 -> 0 | E12: =4+5+1 -> 10 | K12: Proben ziehen, auf EW-Pal. packen und an Rotex liefern | L12: 4+5 Trays auf 1 EW-Pal.
A13: 43137 | B13: =18+42 -> 60 | C13: 0 | D13: =B13-C13 -> 60 | K13: 498769, 498770, 498771, 498772, 498773, 498774, 498775, 498776, 498777, 498778, 498779, 498780, 498781, 498782, 498812, 498813, 498814, 498815, 498816, 498817, 498818, 498819, 498820, 498821, 498822, 498823, 498824, 498783, 498784, 498785, 498786, 498787, 498788, 498789, 498790, 498791, 498792, 498793, 498794, 498795, 498796, 498797, 498798, 498799, 498800, 498801, 498802, 498803, 498804, 498805, 498806, 498807, 498808, 498809, 498810, 498811, 000043, 000044, 000045, 000046
A14: 43140 | B14: 0 | C14: 8 | D14: =B14-C14 -> -8 | K14: 496618, 496619, 496620, 496605, 496607, 491582, 491583, 496632
A15: 43140 | B15: 4 | C15: 0 | D15: =B15-C15 -> 4 | K15: 498941, 498942, 498943, 498944
A16: 43144 | B16: 0 | C16: 2 | D16: =B16-C16 -> -2 | K16: 490082, 490083
A17: 43144 | B17: 13 | C17: 0 | D17: =B17-C17 -> 13 | K17: 499118, 499119, 499120, 499121, 499124, 499127, 499128, 499129, 499130, 499133, 499134, 499135, 499136
A18: 43146 | B18: 0 | C18: 17 | D18: =B18-C18 -> -17 | K18: 497905, 497906, 497907, 498769, 498770, 498771, 498772, 498773, 498774, 498775, 498776, 498777, 498778, 498779, 497780, 498781, 498782
A19: 43147 | B19: 0 | C19: 20 | D19: =B19-C19 -> -20 | K19: 497515, 497516, 497517, 497518, 497519, 497520, 497521, 497522, 497523, 497524, 497525, 497526, 497527, 497037, 488661, 488662, 497036, 490302, 498362, 498363
A20: 43147 | B20: 16 | C20: 0 | D20: =B20-C20 -> 16 | K20: 499452, 499453, 499454, 499455, 499456, 499457, 499458, 499459, 499460, 499461, 499462, 499463, 499464, 499465, 499466, 499467
A21: 43150 | B21: 0 | C21: 20 | D21: =B21-C21 -> -20 | K21: 498064, 498065, 498066, 498067, 498068, 498069, 497528, 467529, 497530, 497531, 497532, 497533, 497908, 494951, 494952, 493876, 493877, 493878, 493364, 493365
A22: 43154 | B22: 0 | C22: 19 | D22: =B22-C22 -> -19 | K22: 497481, 498070, 460805, 497038, 497379, 494953, 494954, 487761, 497909, 496633, 496635, 496636, 496637, 496621, 496622, 496623, 496624, 496625, 498366
A23: 43154 | B23: 11 | C23: 0 | D23: =B23-C23 -> 11 | K23: 499803, 499804, 499805, 499806, 499807, 499808, 499809, 499810, 499811, 499812, 499813
D24: =B24-C24 -> 0
D25: =B25-C25 -> 0
D26: =B26-C26 -> 0
D27: =B27-C27 -> 0
D28: =B28-C28 -> 0
D29: =B29-C29 -> 0
D30: =B30-C30 -> 0
D31: =B31-C31 -> 0
D32: =B32-C32 -> 0
D33: =B33-C33 -> 0
D34: =B34-C34 -> 0
D35: =B35-C35 -> 0
... D44: =B44-C44 -> 0

Sheet 03.18
A1: Rotexmedica Lager | J1: Kontingent: | K1: =288+132+36+36 -> 492
F2: Übertrag aus Vormonat: | J2: Verfügbar: | K2: =K1-F6 -> 103
F3: ='02.18'!F6 -> 418
A4: Datum | B4: Ein- lagerung | C4: Aus- lagerung | D4: Zu- / Abgang | E4: Extra Handling | F4: Lagerbestand ist | G4: Bewegung Einlagerung | H4: Bewegung Auslagerung | J4: Summe Bewegungen | K4: EB-Nummer(n)
L5: Traffic Bewegungen : Kontingent
F6: =SUM(D:D)+F3 -> 389 | G6: =SUM(B:B) -> 99 | H6: =SUM(C:C) -> 128 | J6: =SUM(G6:H6)+SUM(E:E) -> 229 | L6: =J6/K1 -> 0.46544715
A7: 43161 | B7: 0 | C7: 20 | D7: =B7-C7 -> -20 | K7: 498783, 498784, 498785, 498786, 498787, 498788, 498789, 498790, 498791, 498792, 498793, 498794, 498795, 498796, 498797, 498798, 498367, 498368, 498369, 498370
A8: 43164 | B8: 0 | C8: 2 | D8: =B8-C8 -> -2 | K8: 479308, 479310
A9: 43165 | B9: 0 | C9: 19 | D9: =B9-C9 -> -19 | K9: 498071, 498072, 498073, 498074, 498075, 498076, 498077, 498078, 486252, 486253, 486254, 486255, 486256, 486257, 486258, 486259, 486260, 486261, 486262
A10: 43165 | B10: 0 | C10: 0 | D10: =B10-C10 -> 0 | E10: 2 | K10: "Regalbau" 2 Packstücke, gesamt 354x113x113 = 4,5 kbm | L10: Blocklager! Abrg. Lagergeld erfolgt gesondert über Rg. Pos.4
A11: 43172 | B11: 0 | C11: 3 | D11: =B11-C11 -> -3 | K11: 498079, 498080, 498081
A12: 43172 | B12: 0 | C12: 10 | D12: =B12-C12 -> -10 | K12: 498371, 498372, 498373, 498375, 499118, 497039, 497040, 497041, 497042, 497043
A13: 43172 | B13: 0 | C13: 8 | D13: =B13-C13 -> -8 | K13: 498799, 498800, 498801, 498802, 498803, 498804, 498805, 498806
A14: 43172 | B14: 14 | C14: 0 | D14: =B14-C14 -> 14 | K14: 500706, 500707, 500708, 500709, 500710, 500711, 500712, 500713, 500714, 500715, 500716, 500717, 500718, 500719
A15: 43173 | B15: 0 | C15: 9 | D15: =B15-C15 -> -9 | K15: 498807, 498808, 498809, 498810, 498811, 498941, 498942, 498943, 498944
A16: 43175 | B16: 0 | C16: 21 | D16: =B16-C16 -> -21 | K16: 498812, 498813, 498814, 498815, 498816, 498817, 498818, 498819, 498820, 498821, 498822, 498823, 498824, 497930, 497931, 497932, 497933, 497934, 497935, 497936, 495672
A17: 43175 | B17: 6 | C17: 0 | D17: =B17-C17 -> 6 | K17: 501008, 501009, 501010, 501011, 501012, 501013
A18: 43175 | B18: 0 | C18: 8 | D18: =B18-C18 -> -8 | K18: 494955, 494956, 493879, 497180, 497181, 487762, 497068, 494957
A19: 43178 | B19: 0 | C19: 5 | D19: =B19-C19 -> -5 | K19: 499452, 499453, 499454, 499455, 498150
A20: 43178 | B20: 35 | C20: 0 | D20: =B20-C20 -> 35 | K20: 501092, 501093, 501094, 501095, 501096, 501097, 501098, 501099, 501100, 501101, 501102, 501103, 501104, 501105, 501106, 501107, 501108, 501109, 501110, 501111, 501112, 501113, 501114, 501115, 501116, 501117, 501118, 501119, 501120, 501121, 501122, 501123, 501124, 501125, 501126
A21: 43180 | B21: 21 | C21: 0 | D21: =B21-C21 -> 21 | K21: 501339, 501340, 501341, 501342, 501343, 501344, 501345, 501346, 501347, 501348, 501349, 501350, 501351, 501352, 501353, 501354, 501355, 501356, 501357, 501358, 501359
A22: 43185 | B22: 0 | C22: 5 | D22: =B22-C22 -> -5 | K22: 494958, 494959, 494960, 497182, 497069
... A26: 43188 | B26: 13 | C26: 0 | D26: =B26-C26 -> 13 | K26: 501868, 501869, 501870, 501871, 501872, 501874, 501875, 501876, 501877, 501878, 501879, 501880, 501881
D27: =B27-C27 -> 0
D28: =B28-C28 -> 0
D29: =B29-C29 -> 0
D30: =B30-C30 -> 0
D31: =B31-C31 -> 0
D32: =B32-C32 -> 0
D33: =B33-C33 -> 0
D34: =B34-C34 -> 0
D35: =B35-C35 -> 0
D36: =B36-C36 -> 0
D37: =B37-C37 -> 0
D38: =B38-C38 -> 0
... D44: =B44-C44 -> 0

Sheet 04.18
A1: Rotexmedica Lager | J1: Kontingent: | K1: =288+132+36+36 -> 492
F2: Übertrag aus Vormonat: | J2: Verfügbar: | K2: =K1-F6 -> 14
F3: ='03.18'!F6 -> 389
A4: Datum | B4: Ein- lagerung | C4: Aus- lagerung | D4: Zu- / Abgang | E4: Extra Handling | F4: Lagerbestand ist | G4: Bewegung Einlagerung | H4: Bewegung Auslagerung | J4: Summe Bewegungen | K4: EB-Nummer(n)
L5: Traffic Bewegungen : Kontingent
F6: =SUM(D:D)+F3 -> 478 | G6: =SUM(B:B) -> 208 | H6: =SUM(C:C) -> 119 | J6: =SUM(G6:H6)+SUM(E:E) -> 393 | L6: =J6/K1 -> 0.79878049
A7: 43193 | B7: 21 | C7: 0 | D7: =B7-C7 -> 21 | K7: 501904, 501905, 501906, 501907, 501908, 501895, 501896, 501897, 501898, 501915, 501916, 501917, 501918, 501919, 501920, 501927, 501928, 501929, 501930, 501931, 501926
A8: 43194 | B8: 0 | C8: 5 | D8: =B8-C8 -> -5 | K8: 497937, 497938, 497939, 497940, 497941 | L8: Sonderfahrt
A9: 43194 | B9: 0 | C9: 2 | D9: =B9-C9 -> -2 | K9: 499803, 499804 | L9: Sonderfahrt
A10: 43195 | B10: 23 | C10: 0 | D10: =B10-C10 -> 23 | K10: 502148, 502149, 502150, 502151, 502152, 502153, 502154, 502155, 502156, 502157, 502158, 502159, 502160, 502161, 502162, 502163, 502164, 502169, 502170, 502171, 502172, 502173, 502175
A11: 43199 | B11: 0 | C11: 14 | D11: =B11-C11 -> -14 | K11: 490337, 490338, 490342, 490343, 500706, 500707, 500708, 500709, 476270, 476271, 476272, 496846, 496847, 496848
A12: 43200 | B12: 10 | C12: 0 | D12: =B12-C12 -> 10 | K12: 502439, 502440, 502441, 502443, 502444, 502445, 502447, 502448, 502449, 502451
A13: 43201 | D13: =B13-C13 -> 0 | E13: 36 | K13: Handling Zwischenlager Block - Paletten labeln
A14: 43201 | D14: =B14-C14 -> 0 | E14: 4 | K14: Proben ziehen und an Rotex liefern
A15: 43201 | B15: 36 | C15: 0 | D15: =B15-C15 -> 36 | K15: 502551, 505552, 502553, 502554, 502555, 502556, 502557, 502558, 502559, 502560, 502561, 502562, 502563, 502564, 502565, 502566, 502567, 502568, 502569, 502570, 502571, 502572, 502573, 502573, 502574, 502575, 502576, 502577, 502578, 502579, 502580, 502581, 502582, 502583, 502584, 502586
A16: 43202 | B16: 0 | C16: 2 | D16: =B16-C16 -> -2 | K16: 459743, 459744 | L16: Sonderfahrt
A17: 43202 | B17: 0 | C17: 30 | D17: =B17-C17 -> -30 | K17: 497144, 497145, 500710, 500711, 500712, 500713, 500714, 500715, 498096, 498097, 498098, 498099, 498100, 497942, 497943, 497944, 497945, 497946, 497947, 497948, 497949, 497950, 497951, 494961, 494962, 494963, 497183, 497184, 497071, 000045
A18: 43207 | B18: 0 | C18: 3 | D18: =B18-C18 -> -3 | K18: 497910, 497911, 501545
A19: 43207 | B19: 20 | C19: 0 | D19: =B19-C19 -> 20 | K19: 502859, 502860, 502861, 502862, 502863, 502864, 502865, 502866, 502877, 502878, 502879, 502870, 502871, 502872, 502873, 502874, 502875, 000045, 000047-A, 000047-B
A20: 43208 | D20: =B20-C20 -> 0 | E20: 26 | K20: Handling Zwischenlager Block - Paletten labeln
A21: 43208 | B21: 26 | C21: 0 | D21: =B21-C21 -> 26 | K21: 503010, 503011, 503012, 503013, 501314, 503015, 503016, 503017, 503018, 503019, 503020, 503021, 503022, 503023, 503024, 503025, 503026, 503027, 503028, 503029, 503030, 503031, 503032, 503033, 503034, 503035
A22: 43209 | B22: 0 | C22: 44 | D22: =B22-C22 -> -44 | K22: 497952, 497953, 497954, 497955, 497956, 497957, 497958, 501099, 501100, 501101, 501102, 501103, 501104, 501105, 501106, 501107, 501108, 501109, 501110, 501111, 501112, 501113, 501114, 501115, 501116, 501117, 500716, 500717, 500718, 500719, 501339, 501340, 501341, 501342, 501343, 501344, 501345, 501346, 501347, 501348, 501349, 501350, 501351, 497380
A23: 43209 | B23: 48 | C23: 0 | D23: =B23-C23 -> 48 | K23: 503060, 503061, 503064, 503059, 503063, 503058, 503062, 503080, 503089, 503088, 503090, 503091, 503092, 503093, 503083, 503077, 503079, 503087, 503086, 503082, 503085, 503084, 503081, 503078, 501564, 501565, 501566, 501567, 502072, 502071, 469548, 498913, 498914, 498915, 476271, 499777, 486261, 469547, 469550, 486260, 501569, 501570, 486259, 480833, 480384, 480835, 476270, 501568
A24: 43213 | B24: 0 | C24: 5 | D24: =B24-C24 -> -5 | K24: 431519, 496608, 496609, 496610, 497073
A25: 43213 | B25: 9 | C25: 0 | D25: =B25-C25 -> 9 | K25: 503386, 503387, 503388, 503260, 503265, 503264, 503263, 503262, 503261
A26: 43215 | B26: 0 | C26: 4 | D26: =B26-C26 -> -4 | K26: 496611, 496612, 496613, 496614
A27: 43215 | B27: 5 | C27: 0 | D27: =B27-C27 -> 5 | K27: 503410, 503411, 503412, 503413, 503414
A28: 43217 | B28: 0 | C28: 1 | D28: =B28-C28 -> -1 | K28: eb0ArbKor
A29: 43217 | B29: 10 | C29: 0 | D29: =B29-C29 -> 10 | K29: 503894, 503895, 503896, 503897, 503898, 503899, 503900, 503901, 503902, 503903
A30: 43217 | B30: 0 | C30: 9 | D30: =B30-C30 -> -9 | K30: 499805, 499806, 499807, 499808, 499809, 499810, 499811, 499812, 501352
D31: =B31-C31 -> 0
D32: =B32-C32 -> 0
D33: =B33-C33 -> 0
D34: =B34-C34 -> 0
D35: =B35-C35 -> 0
D36: =B36-C36 -> 0
D37: =B37-C37 -> 0
D38: =B38-C38 -> 0
D39: =B39-C39 -> 0
D40: =B40-C40 -> 0
...

Sheet 05.18
A1: Rotexmedica Lager | J1: Kontingent: | K1: =288+132+36+36+102 -> 594
F2: Übertrag aus Vormonat: | J2: Verfügbar: | K2: =K1-F6 -> 44
F3: ='04.18'!F6 -> 478
A4: Datum | B4: Ein- lagerung | C4: Aus- lagerung | D4: Zu- / Abgang | E4: Extra Handling | F4: Lagerbestand ist | G4: Bewegung Einlagerung | H4: Bewegung Auslagerung | J4: Summe Bewegungen | K4: EB-Nummer(n)
L5: Traffic Bewegungen : Kontingent
F6: =SUM(D:D)+F3 -> 550 | G6: =SUM(B:B) -> 218 | H6: =SUM(C:C) -> 146 | J6: =SUM(G6:H6)+SUM(E:E) -> 412 | L6: =J6/K1 -> 0.69360269
A7: 43222 | B7: 0 | C7: 18 | D7: =B7-C7 -> -18 | K7: 501118, 501119, 501120, 501121, 501122, 501123, 501124, 501125, 502148, 502149, 498151, 486259, 486260, 486261, 486263, 498507, 498508, 498509
A8: 43222 | B8: 8 | C8: 0 | D8: =B8-C8 -> 8 | K8: 504000, 504001, 504002, 504003, 503997, 503998, 503999, ArbKor
A9: 43224 | B9: 0 | C9: 17 | D9: =B9-C9 -> -17 | K9: 496626, 496627, 496628, 496629, 502169, 502170, 502171, 502172, 502173, 502175, 502150, 502151, 502152, 502153, 502154, 502155, 498152
A10: 43224 | B10: 0 | C10: 1 | D10: =B10-C10 -> -1 | K10: 501126 | L10: Sonderfahrt
A11: 43224 | B11: 18 | C11: 0 | D11: =B11-C11 -> 18 | K11: 504326, 504327, 504328, 504329, 504330, 504331, 504332, 504333, 504334, 504335, 504336, 504337, 504338, 504339, 504321, 504322, 504323, 504324
A12: 43228 | B12: 2 | C12: 2 | D12: =B12-C12 -> 0 | E12: 2 | K12: 503010, 418776 (jeweils Muster ziehen)
A13: 43228 | B13: 0 | C13: 8 | D13: =B13-C13 -> -8 | K13: 501008, 501009, 501010, 501011, 499129, 499130, 499133, 499134
A14: 43228 | B14: 0 | C14: 3 | D14: =B14-C14 -> -3 | K14: 496638, 496639, 501915
A15: 43228 | B15: 0 | C15: 2 | D15: =B15-C15 -> -2 | K15: 498153, 498154 | L15: Sonderfahrt
A16: 43228 | B16: 16 | C16: 0 | D16: =B16-C16 -> 16 | K16: 504496, 504495, 504494, 504493, 504492, 504487, 504486, 504482, 504481, 504480, 504479, 504478, 504477, 504476, 504475, 504474
A17: 43228 | B17: 0 | C17: 1 | D17: =B17-C17 -> -1 | K17: 501868 | L17: Sonderfahrt
A18: 43229 | B18: 0 | C18: 19 | D18: =B18-C18 -> -19 | K18: 501869, 501870, 471868, 497074, 501546, 501547, 497146, 497147, 487851, 502551, 502156, 502157, 502158, 502159, 502160, 502161, 502162, 502163, 502164
A19: 43229 | B19: 0 | C19: 2 | D19: =B19-C19 -> -2 | K19: 497498, 497497 | L19: Sonderfahrt
A20: 43229 | B20: 9 | C20: 0 | D20: =B20-C20 -> 9 | K20: 504487, 504589, 504591, 504592, 504593, 504594, 502368, 502370, 502371
A21: 43234 | B21: 23 | C21: 0 | D21: =B21-C21 -> 23 | K21: 504720, 504719, 504718, 504717, 504714, 504713, 504712, 504711, 504710, 504709, 504708, 504707, 504706, 504705, 504704, 504703, 504702, 504701, 504700, 504699, 504698, 504697, 504696
A22: 43235 | B22: 0 | C22: 13 | D22: =B22-C22 -> -13 | K22: 498101, 498102, 498155, 502552, 502553, 502554, 502555, 502556, 502557, 502558, 502559, 502560, 502561
A23: 43235 | B23: 17 | C23: 0 | D23: =B23-C23 -> 17 | K23: 504781, 504782, 504783, 504784, 504785, 504786, 504792, 504793, 504794, 504795, 504796, 504797, 504798, 504801, 504802, 504803, 504804
A24: 43237 | B24: 0 | C24: 4 | D24: =B24-C24 -> -4 | K24: 499813, 503058, 503059, 503060 | L24: Sonderfahrt bis 06:00 Uhr! (957kg)
A25: 43237 | B25: 0 | C25: 0 | D25: =B25-C25 -> 0 | E25: 42 | K25: Handling Zwischenlager Block - Paletten labeln
A26: 43237 | B26: 42 | C26: 0 | D26: =B26-C26 -> 42 | K26: 505022, 505023, 505024, 505025, 505026, 505027, 505028, 505029, 505030, 505031, 505032, 505033, 505034, 505035, 505036, 505037, 505038, 505039, 505040, 505041, 505042, 505043, 505044, 505045, 505046, 505047, 505048, 505049, 505050, 505051, 505052, 505053, 505054, 505055, 505056, 505057, 505058, 505059, 505060, 505061, 505062, 505063 | L26: Lager-Erweiterung ab heute (+102 Block F) auf 594 Plätze
A27: 43238 | B27: 0 | C27: 10 | D27: =B27-C27 -> -10 | K27: 501916, 501917, 501918, 501919, 501920, 501871, 501872, 497185, 497187, 497188
A28: 43242 | B28: 4 | C28: 4 | D28: =B28-C28 -> 0 | E28: 4 | K28: 504714, 505057, 505051, 505022 (jeweils Muster ziehen)
A29: 43242 | B29: 0 | C29: 23 | D29: =B29-C29 -> -23 | K29: 501926, 504801, 504802, 504803, 504804, 503387, 503388, 496615, 496616, 502870, 502871, 502872, 499135, 499136, 502439, 502440, 502441, 502443, 501012, 501013, 502562, 502563, 502564
A30: 43243 | B30: 0 | C30: 4 | D30: =B30-C30 -> -4 | K30: 496849, 496850, 501548, 501549
A31: 43244 | B31: 0 | C31: 13 | D31: =B31-C31 -> -13 | K31: 502565, 502566, 502567, 502568, 502569, 502570, 497482, 497483, 497484, 497485, 498156, 498157, 498158
A32: 43244 | B32: 50 | C32: 0 | D32: =B32-C32 -> 50 | K32: 486166, 496525, 500933, 497032, 502173, 498160, 501745, 501744, 501743, 501742, 501741, 498161, 498162, 498163, 483039, 486314, 505166, 501747, 501748, 501749, 501750, 484543, 491589, 495334, 499773, 505312, 505313, 505314, 505315, 505316, 505340, 505349, 505350, 505351, 505352, 505353, 505355, 505356, 505357, 505358, 505359, 505360, 505361, 505362, 505363, 505364, 505365, 505366, 505367, 505368
A33: 43245 | B33: 12 | C33: 0 | D33: =B33-C33 -> 12 | K33: 505514, 505515, 505516, 505517, 505518, 505519, 505520, 505521, 000048, 000049, 000050-A, 000050-B
A34: 43250 | B34: 0 | C34: 2 | D34: =B34-C34 -> -2 | K34: 504792, 504793
A35: 43250 | B35: 7 | C35: 0 | D35: =B35-C35 -> 7 | K35: 505692, 505693, 505687, 505688, 505689, 505690, 505691
A36: 43251 | B36: 10 | C36: 0 | D36: =B36-C36 -> 10 | K36: 505753, 505754, 505755, 505756, 505757, 505758, 505759, 505760, 505761, 505762
D37: =B37-C37 -> 0
D38: =B38-C38 -> 0
D39: =B39-C39 -> 0
D40: =B40-C40 -> 0
...

Sheet 06.18
A1: Rotexmedica Lager | J1: Kontingent: | K1: =288+132+36+36+102 -> 594
F2: Übertrag aus Vormonat: | J2: Verfügbar: | K2: =K1-F6 -> 166
F3: ='05.18'!F6 -> 550
A4: Datum | B4: Ein- lagerung | C4: Aus- lagerung | D4: Zu- / Abgang | E4: Extra Handling | F4: Lagerbestand ist | G4: Bewegung Einlagerung | H4: Bewegung Auslagerung | J4: Summe Bewegungen | K4: EB-Nummer(n)
L5: Traffic Bewegungen : Kontingent
F6: =SUM(D:D)+F3 -> 428 | G6: =SUM(B:B) -> 87 | H6: =SUM(C:C) -> 209 | J6: =SUM(G6:H6)+SUM(E:E) -> 335 | L6: =J6/K1 -> 0.56397306
A7: 43252 | B7: 0 | C7: 9 | D7: =B7-C7 -> -9 | K7: 502571, 502572, 502573, 502574, 502575, 502576, 502577, 501550, 501551 | L7: Sonderfahrt LKW
A8: 43252 | B8: 0 | C8: 3 | D8: =B8-C8 -> -3 | K8: 498159, 503064, 505349 | L8: Sonderfahrt Sprinter
A9: 43255 | B9: 0 | C9: 12 | D9: =B9-C9 -> -12 | K9: 497486, 497494, 497495, 501353, 501354, 503077, 503078, 503079, 503080, 502444, 502445, 502447
A10: 43257 | B10: 0 | C10: 4 | D10: =B10-C10 -> -4 | K10: 504696, 504697, 504698, 504699 | L10: Sonderfahrt LKW
A11: 43258 | B11: 0 | C11: 11 | D11: =B11-C11 -> -11 | K11: 501552, 501553, 502578, 502579, 502580, 502581, 502582, 502583, 502584, 502585, 502586
A12: 43258 | B12: 14 | C12: 0 | D12: =B12-C12 -> 14 | K12: 506266, 506265, 506264, 506263, 506262, 506261, 506260, 506259, 506258, 506257, 506256, 506255, 506254, 506253
A13: 43259 | B13: 3 | C13: 3 | D13: =B13-C13 -> 0 | K13: 000007, 000008, 000013 | L13: 08.06./12:00 @ HIGHSPEED: Bitte Pal. zur Besichtigung bereitstellen, Rotexmedica Herr Ihde (07,08,13), danach wieder einlagern
A14: 43259 | B14: 0 | C14: 14 | D14: =B14-C14 -> -14 | K14: 492001, 492002, 492003, 503061, 503062, 503063, 501355, 501356, 501357, 501358, 505367, 505368, 497496, 504700
A15: 43259 | D15: =B15-C15 -> 0 | E15: 36 | K15: Handling Zwischenlager Block - Paletten labeln
A16: 43259 | B16: 15 | C16: 0 | D16: =B16-C16 -> 15 | K16: 506346, 506344, 506342, 506341, 506339, 506338, 506337, 506336, 506335, 506334, 506333, 506332, 506331, 506330, 506329
A17: 43259 | B17: 1 | C17: 0 | D17: =B17-C17 -> 1 | K17: 1 Pal. Akten zur Vernichtung Herr Ihde
A18: 43262 | B18: 36 | C18: 0 | D18: =B18-C18 -> 36 | K18: 506424, 506425, 506426, 506427, 506428, 506429, 506430, 506431, 506432, 506433, 506434, 506435, 506436, 506437, 506438, 506439, 506440, 506441, 506442, 506443, 506444, 506445, 506446, 506447, 506448, 506449, 506450, 506451, 506452, 506453, 506454, 506455, 506456, 506457, 506458, 506459
A19: 43262 | B19: 3 | C19: 3 | D19: =B19-C19 -> 0 | E19: 3 | K19: 479023, 476270, 502173 (je 2 Bulks Muster ziehen)
A20: 43262 | B20: 0 | C20: 3 | D20: =B20-C20 -> -3 | K20: ArbKor, 000007, 000013 | L20: 007 + 013 z.Hd. Herr Ihde
A21: 43263 | B21: 0 | C21: 14 | D21: =B21-C21 -> -14 | K21: 502448, 502449, 502451, 503260, 506424, 506425, 506426, 506427, 506428, 506429, 506430, 506431, 506264, 506265
A22: 43263 | B22: 0 | C22: 2 | D22: =B22-C22 -> -2 | K22: 493471, 493472 | L22: Sonderfahrt Sprinter
A23: 43263 | B23: 1 | C23: 1 | D23: =B23-C23 -> 0 | K23: 000008 | L23: 12.06./12:00 @ HIGHSPEED: Bitte Pal. zur Besichtigung bereitstellen, Rotexmedica Herr Ihde (000008), danach wieder einlagern
A24: 43263 | B24: 1 | C24: 0 | D24: =B24-C24 -> 1 | K24: ArbKor
A25: 43264 | B25: 0 | C25: 7 | D25: =B25-C25 -> -7 | K25: 506259, 501554, 502873, 502874, 496630, 496671, 504701
A26: 43264 | B26: 6 | C26: 0 | D26: =B26-C26 -> 6 | K26: 506618, 506619, 506620, 506621, 506622, 506623
A27: 43264 | B27: 0 | C27: 2 | D27: =B27-C27 -> -2 | K27: 506258, 503386 | L27: Sonderfahrt Sprinter
A28: 43265 | B28: 0 | C28: 31 | D28: =B28-C28 -> -31 | K28: 1 Pal. Akten zur Vernichtung Herr Ihde 505355, 505356, 505357, 503084, 480833, 501874, 501875, 502859, 502860, 503410, 503261, 503262, 503263, 503264, 501904, 501905, 501906, 506432, 506433, 506434, 506435, 506436, 506437, 506438, 506439, 506440, 506441, 506442, 506443, 506444
A29: 43269 | B29: 0 | C29: 3 | D29: =B29-C29 -> -3 | K29: 480834, 471869, 502861 | L29: Sonderfahrt 2xSprinter
A30: 43270 | B30: 0 | C30: 16 | D30: =B30-C30 -> -16 | K30: 504794, 504795, 506260, 506261, 502875, 504781, 495673, 495674, 000046, 501876, 502862, 501741, 501742, 501743, 501744, 501745
A31: 43273 | B31: 0 | C31: 23 | D31: =B31-C31 -> -23 | K31: 503997, 501359, 504327, 504328, 504329, 504330, 504331, 504332, 504333, 504334, 504335, 504326, 502071, 503085, 503086, 497916, 497917, 497918, 497919, 497920, 497921, 497922, 493464
A32: 43276 | B32: 0 | C32: 2 | D32: =B32-C32 -> -2 | K32: 499777, 502072 | L32: Sonderfahrt Sprinter
A33: 43277 | B33: 7 | C33: 0 | D33: =B33-C33 -> 7 | K33: 507144, 507145, 507146, 507147, 507148, 507149, 507150
A34: 43278 | B34: 0 | C34: 1 | D34: =B34-C34 -> -1 | K34: 503998 | L34: Sonderfahrt Sprinter
A35: 43279 | B35: 0 | C35: 45 | D35: =B35-C35 -> -45 | K35: 505358, 505359, 505360, 505361, 493016, 493017, 493018, 501747, 503999, 504000, 504001, 504002, 504702, 504703, 504704, 504705, 504706, 504707, 497923, 497924, 497925, 497926, 497927, 497928, 497929, 501092, 501093, 501094, 501095, 501096, 492102, 492103, 492104, 501877, 495675, 495676, 501895, 506253, 506254, 506266, 502877, 501927, 504782, 504783, 501564
D36: =B36-C36 -> 0
D37: =B37-C37 -> 0
D38: =B38-C38 -> 0
D39: =B39-C39 -> 0
D40: =B40-C40 -> 0
...

Sheet 07.18
A1: Rotexmedica Lager | J1: Kontingent: | K1: =288+132+36+36+102 -> 594
F2: Übertrag aus Vormonat: | J2: Verfügbar: | K2: =K1-F6 -> 138
F3: ='06.18'!F6 -> 428
A4: Datum | B4: Ein- lagerung | C4: Aus- lagerung | D4: Zu- / Abgang | E4: Extra Handling | F4: Lagerbestand ist | G4: Bewegung Einlagerung | H4: Bewegung Auslagerung | J4: Summe Bewegungen | K4: EB-Nummer(n)
L5: Traffic Bewegungen : Kontingent
F6: =SUM(D:D)+F3 -> 456 | G6: =SUM(B:B) -> 46 | H6: =SUM(C:C) -> 18 | J6: =SUM(G6:H6)+SUM(E:E) -> 67 | L6: =J6/K1 -> 0.11279461
A7: 43283 | B7: 0 | C7: 1 | D7: =B7-C7 -> -1 | K7: 501907 | L7: Sonderfahrt Sprinter
A8: 43284 | B8: 0 | C8: 2 | D8: =B8-C8 -> -2 | K8: 504708, 504709 | L8: Sonderfahrt Sprinter
A9: 43285 | B9: 0 | C9: 1 | D9: =B9-C9 -> -1 | K9: 504710 | L9: Sonderfahrt Sprinter
A10: 43287 | B10: 0 | C10: 6 | D10: =B10-C10 -> -6 | K10: 000018A, 000018B, 000019A, 000019B, 000047A, 000047B
A11: 43287 | B11: 16 | C11: 0 | D11: =B11-C11 -> 16 | K11: 507920, 507921, 507922, 507923, 507924, 507925, 507926, 507927, 507928, 507929, 507930, 507931, 507932, 507933, 507934, 507935
A12: 43299 | B12: 0 | C12: 3 | D12: =B12-C12 -> -3 | K12: 474889, 463709, 422536
A13: 43299 | B13: 27 | C13: 0 | D13: =B13-C13 -> 27 | K13: 505730, 505731, 505732, 505733, 505734, 505735, 505736, 505737, 505738, 505739, 506819, 506820, 506821, 506822, 506823, 000047A, 000047B, 000051, 000052, 000053, 000054, 000055, 000056, 000057, 000058, 000059, 000060
A14: 43301 | B14: 0 | C14: 0 | D14: =B14-C14 -> 0 | E14: 2 | K14: eb0Regalbau "Regalbau" 2 Packstücke, gesamt 354x113x113 = 4,5 kbm
A15: 43305 | B15: 3 | C15: 3 | D15: =B15-C15 -> 0 | E15: 1 | K15: 000001, 000002, 000004 Bereitstellung zur Prüfung; Teilentnahme + Neuverpackung von 000004 | L15: Sonderfahrt Kombi
A16: 43307 | B16: 0 | C16: 2 | D16: =B16-C16 -> -2 | K16: 000057, 000041
D17: =B17-C17 -> 0
D18: =B18-C18 -> 0
D19: =B19-C19 -> 0
D20: =B20-C20 -> 0
D21: =B21-C21 -> 0
D22: =B22-C22 -> 0
D23: =B23-C23 -> 0
D24: =B24-C24 -> 0
D25: =B25-C25 -> 0
D26: =B26-C26 -> 0
D27: =B27-C27 -> 0
D28: =B28-C28 -> 0
... D44: =B44-C44 -> 0

Sheet 08.18
A1: Rotexmedica Lager | J1: Kontingent: | K1: =288+132+36+36+102 -> 594
F2: Übertrag aus Vormonat: | J2: Verfügbar: | K2: =K1-F6 -> 196
F3: ='07.18'!F6 -> 456
